<?xml version="1.0" encoding="utf-8"?>
<!-- This URDF was automatically created by SolidWorks to URDF Exporter! Originally created by Stephen Brawner (brawner@gmail.com) 
     Commit Version: 1.6.0-4-g7f85cfe  Build Version: 1.6.7995.38578
     For more information, please see http://wiki.ros.org/sw_urdf_exporter -->
<robot
  name="mz07">
  <link
    name="base_link">
    <inertial>
      <origin
        xyz="-0.033797768609339 -2.24756295124704E-05 0.0999430830021508"
        rpy="0 0 0" />
      <mass
        value="7.47968846364906" />
      <inertia
        ixx="0.0387858772541378"
        ixy="1.38055569604761E-05"
        ixz="-0.00110303527066198"
        iyy="0.0607658473870163"
        iyz="9.94176818690902E-06"
        izz="0.054196912580205" />
    </inertial>
    <visual>
      <origin
        xyz="0 0 0"
        rpy="0 0 0" />
      <geometry>
        <mesh
          filename="package://mz07/meshes/base_link.STL" />
      </geometry>
      <material
        name="">
        <color
          rgba="1 1 1 1" />
      </material>
    </visual>
    <collision>
      <origin
        xyz="0 0 0"
        rpy="0 0 0" />
      <geometry>
        <mesh
          filename="package://mz07/meshes/base_link.STL" />
      </geometry>
    </collision>
  </link>
  <link
    name="Link1">
    <inertial>
      <origin
        xyz="0.014842 1.0345E-05 0.081196"
        rpy="0 0 0" />
      <mass
        value="4.4116" />
      <inertia
        ixx="0.035894"
        ixy="1.0851E-06"
        ixz="-0.0047925"
        iyy="0.023639"
        iyz="-8.8663E-06"
        izz="0.030308" />
    </inertial>
    <visual>
      <origin
        xyz="0 0 0"
        rpy="0 0 0" />
      <geometry>
        <mesh
          filename="package://mz07/meshes/Link1.STL" />
      </geometry>
      <material
        name="">
        <color
          rgba="1 1 1 1" />
      </material>
    </visual>
    <collision>
      <origin
        xyz="0 0 0"
        rpy="0 0 0" />
      <geometry>
        <mesh
          filename="package://mz07/meshes/Link1.STL" />
      </geometry>
    </collision>
  </link>
  <joint
    name="J1"
    type="revolute">
    <origin
      xyz="0 0 0.197"
      rpy="0 0 0" />
    <parent
      link="base_link" />
    <child
      link="Link1" />
    <axis
      xyz="0 0 -1" />
    <limit
      lower="-2.97"
      upper="2.97"
      effort="100"
      velocity="1" />
  </joint>
  <link
    name="Link2">
    <inertial>
      <origin
        xyz="-0.010731 -0.15607 -7.0183E-05"
        rpy="0 0 0" />
      <mass
        value="5.7737" />
      <inertia
        ixx="0.094601"
        ixy="-0.00033428"
        ixz="1.1805E-05"
        iyy="0.027544"
        iyz="0.00010399"
        izz="0.078296" />
    </inertial>
    <visual>
      <origin
        xyz="0 0 0"
        rpy="0 0 0" />
      <geometry>
        <mesh
          filename="package://mz07/meshes/Link2.STL" />
      </geometry>
      <material
        name="">
        <color
          rgba="1 1 1 1" />
      </material>
    </visual>
    <collision>
      <origin
        xyz="0 0 0"
        rpy="0 0 0" />
      <geometry>
        <mesh
          filename="package://mz07/meshes/Link2.STL" />
      </geometry>
    </collision>
  </link>
  <joint
    name="J2"
    type="revolute">
    <origin
      xyz="0.05 0 0.148"
      rpy="-1.5708 0 0" />
    <parent
      link="Link1" />
    <child
      link="Link2" />
    <axis
      xyz="0 0 1" />
    <limit
      lower="-2.36"
      upper="1.40"
      effort="100"
      velocity="1" />
  </joint>
  <link
    name="Link3">
    <inertial>
      <origin
        xyz="-0.0090511 -0.020552 -0.00035077"
        rpy="0 0 0" />
      <mass
        value="2.9259" />
      <inertia
        ixx="0.0079804"
        ixy="0.00090568"
        ixz="-2.4051E-05"
        iyy="0.010878"
        iyz="4.0099E-05"
        izz="0.013867" />
    </inertial>
    <visual>
      <origin
        xyz="0 0 0"
        rpy="0 0 0" />
      <geometry>
        <mesh
          filename="package://mz07/meshes/Link3.STL" />
      </geometry>
      <material
        name="">
        <color
          rgba="1 1 1 1" />
      </material>
    </visual>
    <collision>
      <origin
        xyz="0 0 0"
        rpy="0 0 0" />
      <geometry>
        <mesh
          filename="package://mz07/meshes/Link3.STL" />
      </geometry>
    </collision>
  </link>
  <joint
    name="J3"
    type="revolute">
    <origin
      xyz="0 -0.33 0"
      rpy="0 0 0" />
    <parent
      link="Link2" />
    <child
      link="Link3" />
    <axis
      xyz="0 0 -1" />
    <limit
      lower="-2.37"
      upper="4.71"
      effort="100"
      velocity="1" />
  </joint>
  <link
    name="Link4">
    <inertial>
      <origin
        xyz="0.00021781 0.0009554 -0.14242"
        rpy="0 0 0" />
      <mass
        value="2.5501" />
      <inertia
        ixx="0.015161"
        ixy="1.6771E-05"
        ixz="-1.1985E-06"
        iyy="0.013658"
        iyz="-0.00018313"
        izz="0.005607" />
    </inertial>
    <visual>
      <origin
        xyz="0 0 0"
        rpy="0 0 0" />
      <geometry>
        <mesh
          filename="package://mz07/meshes/Link4.STL" />
      </geometry>
      <material
        name="">
        <color
          rgba="1 1 1 1" />
      </material>
    </visual>
    <collision>
      <origin
        xyz="0 0 0"
        rpy="0 0 0" />
      <geometry>
        <mesh
          filename="package://mz07/meshes/Link4.STL" />
      </geometry>
    </collision>
  </link>
  <joint
    name="J4"
    type="revolute">
    <origin
      xyz="0.34 -0.045 0"
      rpy="1.5708 0 1.5708" />
    <parent
      link="Link3" />
    <child
      link="Link4" />
    <axis
      xyz="0 0 -1" />
    <limit
      lower="-3.32"
      upper="3.32"
      effort="100"
      velocity="1" />
  </joint>
  <link
    name="Link5">
    <inertial>
      <origin
        xyz="0.023041 2.0719E-05 -0.0044788"
        rpy="0 0 0" />
      <mass
        value="0.39427" />
      <inertia
        ixx="0.0004154"
        ixy="-1.6241E-08"
        ixz="-4.1736E-05"
        iyy="0.00053835"
        iyz="-6.3531E-07"
        izz="0.0004912" />
    </inertial>
    <visual>
      <origin
        xyz="0 0 0"
        rpy="0 0 0" />
      <geometry>
        <mesh
          filename="package://mz07/meshes/Link5.STL" />
      </geometry>
      <material
        name="">
        <color
          rgba="1 1 1 1" />
      </material>
    </visual>
    <collision>
      <origin
        xyz="0 0 0"
        rpy="0 0 0" />
      <geometry>
        <mesh
          filename="package://mz07/meshes/Link5.STL" />
      </geometry>
    </collision>
  </link>
  <joint
    name="J5"
    type="revolute">
    <origin
      xyz="0 0 0"
      rpy="1.5708 -1.5708 0" />
    <parent
      link="Link4" />
    <child
      link="Link5" />
    <axis
      xyz="0 0 1" />
    <limit
      lower="-2.09"
      upper="2.09"
      effort="100"
      velocity="1" />
  </joint>
  <link
    name="Link6">
    <inertial>
      <origin
        xyz="-0.00027465 -7.3536E-05 0.070583"
        rpy="0 0 0" />
      <mass
        value="0.030302" />
      <inertia
        ixx="1.1541E-05"
        ixy="7.1157E-08"
        ixz="-9.3007E-09"
        iyy="1.1088E-05"
        iyz="-2.4931E-09"
        izz="2.1471E-05" />
    </inertial>
    <visual>
      <origin
        xyz="0 0 0"
        rpy="0 0 0" />
      <geometry>
        <mesh
          filename="package://mz07/meshes/Link6.STL" />
      </geometry>
      <material
        name="">
        <color
          rgba="1 1 1 1" />
      </material>
    </visual>
    <collision>
      <origin
        xyz="0 0 0"
        rpy="0 0 0" />
      <geometry>
        <mesh
          filename="package://mz07/meshes/Link6.STL" />
      </geometry>
    </collision>
  </link>
  <joint
    name="J6"
    type="revolute">
    <origin
      xyz="0 0 0"
      rpy="1.5708 0 1.5708" />
    <parent
      link="Link5" />
    <child
      link="Link6" />
    <axis
      xyz="0 0 -1" />
    <limit
      lower="-6.28"
      upper="6.28"
      effort="100"
      velocity="1" />
  </joint>
  <link
    name="Tool">
    <inertial>
      <origin
        xyz="-0.00027465 -7.3538E-05 -0.0024173"
        rpy="0 0 0" />
      <mass
        value="0.030302" />
      <inertia
        ixx="1.1541E-05"
        ixy="7.1161E-08"
        ixz="-9.3006E-09"
        iyy="1.1088E-05"
        iyz="-2.4932E-09"
        izz="2.1471E-05" />
    </inertial>
    <visual>
      <origin
        xyz="0 0 0"
        rpy="0 0 0" />
      <geometry>
        <mesh
          filename="package://mz07/meshes/Tool.STL" />
      </geometry>
      <material
        name="">
        <color
          rgba="1 1 1 1" />
      </material>
    </visual>
    <collision>
      <origin
        xyz="0 0 0"
        rpy="0 0 0" />
      <geometry>
        <mesh
          filename="package://mz07/meshes/Tool.STL" />
      </geometry>
    </collision>
  </link>
  <joint
    name="J7"
    type="fixed">
    <origin
      xyz="0 0 0.073"
      rpy="0 0 0" />
    <parent
      link="Link6" />
    <child
      link="Tool" />
    <axis
      xyz="0 0 0" />
  </joint>
</robot>